INFO:root:2020-09-30 16:16:52.442413
ERROR:root:DATABASE
Traceback (most recent call last):
  File "/usr/local/lib/python3.8/site-packages/mysql/connector/connection_cext.py", line 216, in _open_connection
    self._cmysql.connect(**cnx_kwargs)
_mysql_connector.MySQLInterfaceError: Unknown database 'stocktrade'

During handling of the above exception, another exception occurred:

Traceback (most recent call last):
  File "/usr/local/lib/python3.8/site-packages/sqlalchemy/engine/base.py", line 2338, in _wrap_pool_connect
    return fn()
  File "/usr/local/lib/python3.8/site-packages/sqlalchemy/pool/base.py", line 364, in connect
    return _ConnectionFairy._checkout(self)
  File "/usr/local/lib/python3.8/site-packages/sqlalchemy/pool/base.py", line 778, in _checkout
    fairy = _ConnectionRecord.checkout(pool)
  File "/usr/local/lib/python3.8/site-packages/sqlalchemy/pool/base.py", line 495, in checkout
    rec = pool._do_get()
  File "/usr/local/lib/python3.8/site-packages/sqlalchemy/pool/impl.py", line 140, in _do_get
    self._dec_overflow()
  File "/usr/local/lib/python3.8/site-packages/sqlalchemy/util/langhelpers.py", line 68, in __exit__
    compat.raise_(
  File "/usr/local/lib/python3.8/site-packages/sqlalchemy/util/compat.py", line 182, in raise_
    raise exception
  File "/usr/local/lib/python3.8/site-packages/sqlalchemy/pool/impl.py", line 137, in _do_get
    return self._create_connection()
  File "/usr/local/lib/python3.8/site-packages/sqlalchemy/pool/base.py", line 309, in _create_connection
    return _ConnectionRecord(self)
  File "/usr/local/lib/python3.8/site-packages/sqlalchemy/pool/base.py", line 440, in __init__
    self.__connect(first_connect_check=True)
  File "/usr/local/lib/python3.8/site-packages/sqlalchemy/pool/base.py", line 661, in __connect
    pool.logger.debug("Error on connect(): %s", e)
  File "/usr/local/lib/python3.8/site-packages/sqlalchemy/util/langhelpers.py", line 68, in __exit__
    compat.raise_(
  File "/usr/local/lib/python3.8/site-packages/sqlalchemy/util/compat.py", line 182, in raise_
    raise exception
  File "/usr/local/lib/python3.8/site-packages/sqlalchemy/pool/base.py", line 656, in __connect
    connection = pool._invoke_creator(self)
  File "/usr/local/lib/python3.8/site-packages/sqlalchemy/engine/strategies.py", line 114, in connect
    return dialect.connect(*cargs, **cparams)
  File "/usr/local/lib/python3.8/site-packages/sqlalchemy/engine/default.py", line 493, in connect
    return self.dbapi.connect(*cargs, **cparams)
  File "/usr/local/lib/python3.8/site-packages/mysql/connector/__init__.py", line 264, in connect
    return CMySQLConnection(*args, **kwargs)
  File "/usr/local/lib/python3.8/site-packages/mysql/connector/connection_cext.py", line 80, in __init__
    self.connect(**kwargs)
  File "/usr/local/lib/python3.8/site-packages/mysql/connector/abstracts.py", line 966, in connect
    self._open_connection()
  File "/usr/local/lib/python3.8/site-packages/mysql/connector/connection_cext.py", line 218, in _open_connection
    raise errors.get_mysql_exception(msg=exc.msg, errno=exc.errno,
mysql.connector.errors.ProgrammingError: 1049 (42000): Unknown database 'stocktrade'

The above exception was the direct cause of the following exception:

Traceback (most recent call last):
  File "/Users/fredcosta/Projects/Onboarding/StockTrades/tests.py", line 27, in <module>
    dt_repo.add_stocks_info(json_response)
  File "/Users/fredcosta/Projects/Onboarding/StockTrades/db/data_repository.py", line 41, in add_stocks_info
    self.database.add_stocks(stocks)
  File "/Users/fredcosta/Projects/Onboarding/StockTrades/db/stocks_database.py", line 61, in add_stocks
    self.initialize_db()
  File "/Users/fredcosta/Projects/Onboarding/StockTrades/db/stocks_database.py", line 48, in initialize_db
    Base.metadata.create_all(self.engine)
  File "/usr/local/lib/python3.8/site-packages/sqlalchemy/sql/schema.py", line 4555, in create_all
    bind._run_visitor(
  File "/usr/local/lib/python3.8/site-packages/sqlalchemy/engine/base.py", line 2096, in _run_visitor
    with self._optional_conn_ctx_manager(connection) as conn:
  File "/usr/local/Cellar/python@3.8/3.8.5/Frameworks/Python.framework/Versions/3.8/lib/python3.8/contextlib.py", line 113, in __enter__
    return next(self.gen)
  File "/usr/local/lib/python3.8/site-packages/sqlalchemy/engine/base.py", line 2088, in _optional_conn_ctx_manager
    with self._contextual_connect() as conn:
  File "/usr/local/lib/python3.8/site-packages/sqlalchemy/engine/base.py", line 2304, in _contextual_connect
    self._wrap_pool_connect(self.pool.connect, None),
  File "/usr/local/lib/python3.8/site-packages/sqlalchemy/engine/base.py", line 2341, in _wrap_pool_connect
    Connection._handle_dbapi_exception_noconnection(
  File "/usr/local/lib/python3.8/site-packages/sqlalchemy/engine/base.py", line 1583, in _handle_dbapi_exception_noconnection
    util.raise_(
  File "/usr/local/lib/python3.8/site-packages/sqlalchemy/util/compat.py", line 182, in raise_
    raise exception
  File "/usr/local/lib/python3.8/site-packages/sqlalchemy/engine/base.py", line 2338, in _wrap_pool_connect
    return fn()
  File "/usr/local/lib/python3.8/site-packages/sqlalchemy/pool/base.py", line 364, in connect
    return _ConnectionFairy._checkout(self)
  File "/usr/local/lib/python3.8/site-packages/sqlalchemy/pool/base.py", line 778, in _checkout
    fairy = _ConnectionRecord.checkout(pool)
  File "/usr/local/lib/python3.8/site-packages/sqlalchemy/pool/base.py", line 495, in checkout
    rec = pool._do_get()
  File "/usr/local/lib/python3.8/site-packages/sqlalchemy/pool/impl.py", line 140, in _do_get
    self._dec_overflow()
  File "/usr/local/lib/python3.8/site-packages/sqlalchemy/util/langhelpers.py", line 68, in __exit__
    compat.raise_(
  File "/usr/local/lib/python3.8/site-packages/sqlalchemy/util/compat.py", line 182, in raise_
    raise exception
  File "/usr/local/lib/python3.8/site-packages/sqlalchemy/pool/impl.py", line 137, in _do_get
    return self._create_connection()
  File "/usr/local/lib/python3.8/site-packages/sqlalchemy/pool/base.py", line 309, in _create_connection
    return _ConnectionRecord(self)
  File "/usr/local/lib/python3.8/site-packages/sqlalchemy/pool/base.py", line 440, in __init__
    self.__connect(first_connect_check=True)
  File "/usr/local/lib/python3.8/site-packages/sqlalchemy/pool/base.py", line 661, in __connect
    pool.logger.debug("Error on connect(): %s", e)
  File "/usr/local/lib/python3.8/site-packages/sqlalchemy/util/langhelpers.py", line 68, in __exit__
    compat.raise_(
  File "/usr/local/lib/python3.8/site-packages/sqlalchemy/util/compat.py", line 182, in raise_
    raise exception
  File "/usr/local/lib/python3.8/site-packages/sqlalchemy/pool/base.py", line 656, in __connect
    connection = pool._invoke_creator(self)
  File "/usr/local/lib/python3.8/site-packages/sqlalchemy/engine/strategies.py", line 114, in connect
    return dialect.connect(*cargs, **cparams)
  File "/usr/local/lib/python3.8/site-packages/sqlalchemy/engine/default.py", line 493, in connect
    return self.dbapi.connect(*cargs, **cparams)
  File "/usr/local/lib/python3.8/site-packages/mysql/connector/__init__.py", line 264, in connect
    return CMySQLConnection(*args, **kwargs)
  File "/usr/local/lib/python3.8/site-packages/mysql/connector/connection_cext.py", line 80, in __init__
    self.connect(**kwargs)
  File "/usr/local/lib/python3.8/site-packages/mysql/connector/abstracts.py", line 966, in connect
    self._open_connection()
  File "/usr/local/lib/python3.8/site-packages/mysql/connector/connection_cext.py", line 218, in _open_connection
    raise errors.get_mysql_exception(msg=exc.msg, errno=exc.errno,
sqlalchemy.exc.ProgrammingError: (mysql.connector.errors.ProgrammingError) 1049 (42000): Unknown database 'stocktrade'
(Background on this error at: http://sqlalche.me/e/13/f405)
INFO:root:2020-09-30 16:20:03.202344
ERROR:root:DATABASE
Traceback (most recent call last):
  File "/usr/local/lib/python3.8/site-packages/mysql/connector/connection_cext.py", line 216, in _open_connection
    self._cmysql.connect(**cnx_kwargs)
_mysql_connector.MySQLInterfaceError: Unknown database 'stocktrade'

During handling of the above exception, another exception occurred:

Traceback (most recent call last):
  File "/usr/local/lib/python3.8/site-packages/sqlalchemy/engine/base.py", line 2338, in _wrap_pool_connect
    return fn()
  File "/usr/local/lib/python3.8/site-packages/sqlalchemy/pool/base.py", line 364, in connect
    return _ConnectionFairy._checkout(self)
  File "/usr/local/lib/python3.8/site-packages/sqlalchemy/pool/base.py", line 778, in _checkout
    fairy = _ConnectionRecord.checkout(pool)
  File "/usr/local/lib/python3.8/site-packages/sqlalchemy/pool/base.py", line 495, in checkout
    rec = pool._do_get()
  File "/usr/local/lib/python3.8/site-packages/sqlalchemy/pool/impl.py", line 140, in _do_get
    self._dec_overflow()
  File "/usr/local/lib/python3.8/site-packages/sqlalchemy/util/langhelpers.py", line 68, in __exit__
    compat.raise_(
  File "/usr/local/lib/python3.8/site-packages/sqlalchemy/util/compat.py", line 182, in raise_
    raise exception
  File "/usr/local/lib/python3.8/site-packages/sqlalchemy/pool/impl.py", line 137, in _do_get
    return self._create_connection()
  File "/usr/local/lib/python3.8/site-packages/sqlalchemy/pool/base.py", line 309, in _create_connection
    return _ConnectionRecord(self)
  File "/usr/local/lib/python3.8/site-packages/sqlalchemy/pool/base.py", line 440, in __init__
    self.__connect(first_connect_check=True)
  File "/usr/local/lib/python3.8/site-packages/sqlalchemy/pool/base.py", line 661, in __connect
    pool.logger.debug("Error on connect(): %s", e)
  File "/usr/local/lib/python3.8/site-packages/sqlalchemy/util/langhelpers.py", line 68, in __exit__
    compat.raise_(
  File "/usr/local/lib/python3.8/site-packages/sqlalchemy/util/compat.py", line 182, in raise_
    raise exception
  File "/usr/local/lib/python3.8/site-packages/sqlalchemy/pool/base.py", line 656, in __connect
    connection = pool._invoke_creator(self)
  File "/usr/local/lib/python3.8/site-packages/sqlalchemy/engine/strategies.py", line 114, in connect
    return dialect.connect(*cargs, **cparams)
  File "/usr/local/lib/python3.8/site-packages/sqlalchemy/engine/default.py", line 493, in connect
    return self.dbapi.connect(*cargs, **cparams)
  File "/usr/local/lib/python3.8/site-packages/mysql/connector/__init__.py", line 264, in connect
    return CMySQLConnection(*args, **kwargs)
  File "/usr/local/lib/python3.8/site-packages/mysql/connector/connection_cext.py", line 80, in __init__
    self.connect(**kwargs)
  File "/usr/local/lib/python3.8/site-packages/mysql/connector/abstracts.py", line 966, in connect
    self._open_connection()
  File "/usr/local/lib/python3.8/site-packages/mysql/connector/connection_cext.py", line 218, in _open_connection
    raise errors.get_mysql_exception(msg=exc.msg, errno=exc.errno,
mysql.connector.errors.ProgrammingError: 1049 (42000): Unknown database 'stocktrade'

The above exception was the direct cause of the following exception:

Traceback (most recent call last):
  File "/Users/fredcosta/Projects/Onboarding/StockTrades/tests.py", line 23, in save_stocks
    dt_repo.add_stocks_info(json_response)
  File "/Users/fredcosta/Projects/Onboarding/StockTrades/db/data_repository.py", line 41, in add_stocks_info
    self.database.add_stocks(stocks)
  File "/Users/fredcosta/Projects/Onboarding/StockTrades/db/stocks_database.py", line 61, in add_stocks
    self.initialize_db()
  File "/Users/fredcosta/Projects/Onboarding/StockTrades/db/stocks_database.py", line 48, in initialize_db
    Base.metadata.create_all(self.engine)
  File "/usr/local/lib/python3.8/site-packages/sqlalchemy/sql/schema.py", line 4555, in create_all
    bind._run_visitor(
  File "/usr/local/lib/python3.8/site-packages/sqlalchemy/engine/base.py", line 2096, in _run_visitor
    with self._optional_conn_ctx_manager(connection) as conn:
  File "/usr/local/Cellar/python@3.8/3.8.5/Frameworks/Python.framework/Versions/3.8/lib/python3.8/contextlib.py", line 113, in __enter__
    return next(self.gen)
  File "/usr/local/lib/python3.8/site-packages/sqlalchemy/engine/base.py", line 2088, in _optional_conn_ctx_manager
    with self._contextual_connect() as conn:
  File "/usr/local/lib/python3.8/site-packages/sqlalchemy/engine/base.py", line 2304, in _contextual_connect
    self._wrap_pool_connect(self.pool.connect, None),
  File "/usr/local/lib/python3.8/site-packages/sqlalchemy/engine/base.py", line 2341, in _wrap_pool_connect
    Connection._handle_dbapi_exception_noconnection(
  File "/usr/local/lib/python3.8/site-packages/sqlalchemy/engine/base.py", line 1583, in _handle_dbapi_exception_noconnection
    util.raise_(
  File "/usr/local/lib/python3.8/site-packages/sqlalchemy/util/compat.py", line 182, in raise_
    raise exception
  File "/usr/local/lib/python3.8/site-packages/sqlalchemy/engine/base.py", line 2338, in _wrap_pool_connect
    return fn()
  File "/usr/local/lib/python3.8/site-packages/sqlalchemy/pool/base.py", line 364, in connect
    return _ConnectionFairy._checkout(self)
  File "/usr/local/lib/python3.8/site-packages/sqlalchemy/pool/base.py", line 778, in _checkout
    fairy = _ConnectionRecord.checkout(pool)
  File "/usr/local/lib/python3.8/site-packages/sqlalchemy/pool/base.py", line 495, in checkout
    rec = pool._do_get()
  File "/usr/local/lib/python3.8/site-packages/sqlalchemy/pool/impl.py", line 140, in _do_get
    self._dec_overflow()
  File "/usr/local/lib/python3.8/site-packages/sqlalchemy/util/langhelpers.py", line 68, in __exit__
    compat.raise_(
  File "/usr/local/lib/python3.8/site-packages/sqlalchemy/util/compat.py", line 182, in raise_
    raise exception
  File "/usr/local/lib/python3.8/site-packages/sqlalchemy/pool/impl.py", line 137, in _do_get
    return self._create_connection()
  File "/usr/local/lib/python3.8/site-packages/sqlalchemy/pool/base.py", line 309, in _create_connection
    return _ConnectionRecord(self)
  File "/usr/local/lib/python3.8/site-packages/sqlalchemy/pool/base.py", line 440, in __init__
    self.__connect(first_connect_check=True)
  File "/usr/local/lib/python3.8/site-packages/sqlalchemy/pool/base.py", line 661, in __connect
    pool.logger.debug("Error on connect(): %s", e)
  File "/usr/local/lib/python3.8/site-packages/sqlalchemy/util/langhelpers.py", line 68, in __exit__
    compat.raise_(
  File "/usr/local/lib/python3.8/site-packages/sqlalchemy/util/compat.py", line 182, in raise_
    raise exception
  File "/usr/local/lib/python3.8/site-packages/sqlalchemy/pool/base.py", line 656, in __connect
    connection = pool._invoke_creator(self)
  File "/usr/local/lib/python3.8/site-packages/sqlalchemy/engine/strategies.py", line 114, in connect
    return dialect.connect(*cargs, **cparams)
  File "/usr/local/lib/python3.8/site-packages/sqlalchemy/engine/default.py", line 493, in connect
    return self.dbapi.connect(*cargs, **cparams)
  File "/usr/local/lib/python3.8/site-packages/mysql/connector/__init__.py", line 264, in connect
    return CMySQLConnection(*args, **kwargs)
  File "/usr/local/lib/python3.8/site-packages/mysql/connector/connection_cext.py", line 80, in __init__
    self.connect(**kwargs)
  File "/usr/local/lib/python3.8/site-packages/mysql/connector/abstracts.py", line 966, in connect
    self._open_connection()
  File "/usr/local/lib/python3.8/site-packages/mysql/connector/connection_cext.py", line 218, in _open_connection
    raise errors.get_mysql_exception(msg=exc.msg, errno=exc.errno,
sqlalchemy.exc.ProgrammingError: (mysql.connector.errors.ProgrammingError) 1049 (42000): Unknown database 'stocktrade'
(Background on this error at: http://sqlalche.me/e/13/f405)
INFO:root:2020-09-30 16:27:46.515395
ERROR:root:API
Traceback (most recent call last):
  File "/Users/fredcosta/Projects/Onboarding/StockTrades/tests.py", line 16, in save_stocks
    json_response = dt_ex.get_json_response()
  File "/Users/fredcosta/Projects/Onboarding/StockTrades/api/data_extractor.py", line 26, in get_json_response
    response.raise_for_status()
  File "/usr/local/lib/python3.8/site-packages/requests/models.py", line 941, in raise_for_status
    raise HTTPError(http_error_msg, response=self)
requests.exceptions.HTTPError: 401 Client Error: Unauthorized for url: https://cloud.iexapis.com/stable/stock/FB/batch?types=chart&range=1m&last=10
INFO:root:2020-09-30 16:40:26.245857
ERROR:root:DATABASE
Traceback (most recent call last):
  File "/usr/local/lib/python3.8/site-packages/mysql/connector/connection_cext.py", line 216, in _open_connection
    self._cmysql.connect(**cnx_kwargs)
_mysql_connector.MySQLInterfaceError: Access denied for user 'roo'@'172.17.0.1' (using password: YES)

During handling of the above exception, another exception occurred:

Traceback (most recent call last):
  File "/usr/local/lib/python3.8/site-packages/sqlalchemy/engine/base.py", line 2338, in _wrap_pool_connect
    return fn()
  File "/usr/local/lib/python3.8/site-packages/sqlalchemy/pool/base.py", line 364, in connect
    return _ConnectionFairy._checkout(self)
  File "/usr/local/lib/python3.8/site-packages/sqlalchemy/pool/base.py", line 778, in _checkout
    fairy = _ConnectionRecord.checkout(pool)
  File "/usr/local/lib/python3.8/site-packages/sqlalchemy/pool/base.py", line 495, in checkout
    rec = pool._do_get()
  File "/usr/local/lib/python3.8/site-packages/sqlalchemy/pool/impl.py", line 140, in _do_get
    self._dec_overflow()
  File "/usr/local/lib/python3.8/site-packages/sqlalchemy/util/langhelpers.py", line 68, in __exit__
    compat.raise_(
  File "/usr/local/lib/python3.8/site-packages/sqlalchemy/util/compat.py", line 182, in raise_
    raise exception
  File "/usr/local/lib/python3.8/site-packages/sqlalchemy/pool/impl.py", line 137, in _do_get
    return self._create_connection()
  File "/usr/local/lib/python3.8/site-packages/sqlalchemy/pool/base.py", line 309, in _create_connection
    return _ConnectionRecord(self)
  File "/usr/local/lib/python3.8/site-packages/sqlalchemy/pool/base.py", line 440, in __init__
    self.__connect(first_connect_check=True)
  File "/usr/local/lib/python3.8/site-packages/sqlalchemy/pool/base.py", line 661, in __connect
    pool.logger.debug("Error on connect(): %s", e)
  File "/usr/local/lib/python3.8/site-packages/sqlalchemy/util/langhelpers.py", line 68, in __exit__
    compat.raise_(
  File "/usr/local/lib/python3.8/site-packages/sqlalchemy/util/compat.py", line 182, in raise_
    raise exception
  File "/usr/local/lib/python3.8/site-packages/sqlalchemy/pool/base.py", line 656, in __connect
    connection = pool._invoke_creator(self)
  File "/usr/local/lib/python3.8/site-packages/sqlalchemy/engine/strategies.py", line 114, in connect
    return dialect.connect(*cargs, **cparams)
  File "/usr/local/lib/python3.8/site-packages/sqlalchemy/engine/default.py", line 493, in connect
    return self.dbapi.connect(*cargs, **cparams)
  File "/usr/local/lib/python3.8/site-packages/mysql/connector/__init__.py", line 264, in connect
    return CMySQLConnection(*args, **kwargs)
  File "/usr/local/lib/python3.8/site-packages/mysql/connector/connection_cext.py", line 80, in __init__
    self.connect(**kwargs)
  File "/usr/local/lib/python3.8/site-packages/mysql/connector/abstracts.py", line 966, in connect
    self._open_connection()
  File "/usr/local/lib/python3.8/site-packages/mysql/connector/connection_cext.py", line 218, in _open_connection
    raise errors.get_mysql_exception(msg=exc.msg, errno=exc.errno,
mysql.connector.errors.ProgrammingError: 1045 (28000): Access denied for user 'roo'@'172.17.0.1' (using password: YES)

The above exception was the direct cause of the following exception:

Traceback (most recent call last):
  File "/Users/fredcosta/Projects/Onboarding/StockTrades/tests.py", line 26, in save_stocks
    dt_repo.add_stocks_info(json_response)
  File "/Users/fredcosta/Projects/Onboarding/StockTrades/db/data_repository.py", line 41, in add_stocks_info
    self.database.add_stocks(stocks)
  File "/Users/fredcosta/Projects/Onboarding/StockTrades/db/stocks_database.py", line 61, in add_stocks
    self.initialize_db()
  File "/Users/fredcosta/Projects/Onboarding/StockTrades/db/stocks_database.py", line 48, in initialize_db
    Base.metadata.create_all(self.engine)
  File "/usr/local/lib/python3.8/site-packages/sqlalchemy/sql/schema.py", line 4555, in create_all
    bind._run_visitor(
  File "/usr/local/lib/python3.8/site-packages/sqlalchemy/engine/base.py", line 2096, in _run_visitor
    with self._optional_conn_ctx_manager(connection) as conn:
  File "/usr/local/Cellar/python@3.8/3.8.5/Frameworks/Python.framework/Versions/3.8/lib/python3.8/contextlib.py", line 113, in __enter__
    return next(self.gen)
  File "/usr/local/lib/python3.8/site-packages/sqlalchemy/engine/base.py", line 2088, in _optional_conn_ctx_manager
    with self._contextual_connect() as conn:
  File "/usr/local/lib/python3.8/site-packages/sqlalchemy/engine/base.py", line 2304, in _contextual_connect
    self._wrap_pool_connect(self.pool.connect, None),
  File "/usr/local/lib/python3.8/site-packages/sqlalchemy/engine/base.py", line 2341, in _wrap_pool_connect
    Connection._handle_dbapi_exception_noconnection(
  File "/usr/local/lib/python3.8/site-packages/sqlalchemy/engine/base.py", line 1583, in _handle_dbapi_exception_noconnection
    util.raise_(
  File "/usr/local/lib/python3.8/site-packages/sqlalchemy/util/compat.py", line 182, in raise_
    raise exception
  File "/usr/local/lib/python3.8/site-packages/sqlalchemy/engine/base.py", line 2338, in _wrap_pool_connect
    return fn()
  File "/usr/local/lib/python3.8/site-packages/sqlalchemy/pool/base.py", line 364, in connect
    return _ConnectionFairy._checkout(self)
  File "/usr/local/lib/python3.8/site-packages/sqlalchemy/pool/base.py", line 778, in _checkout
    fairy = _ConnectionRecord.checkout(pool)
  File "/usr/local/lib/python3.8/site-packages/sqlalchemy/pool/base.py", line 495, in checkout
    rec = pool._do_get()
  File "/usr/local/lib/python3.8/site-packages/sqlalchemy/pool/impl.py", line 140, in _do_get
    self._dec_overflow()
  File "/usr/local/lib/python3.8/site-packages/sqlalchemy/util/langhelpers.py", line 68, in __exit__
    compat.raise_(
  File "/usr/local/lib/python3.8/site-packages/sqlalchemy/util/compat.py", line 182, in raise_
    raise exception
  File "/usr/local/lib/python3.8/site-packages/sqlalchemy/pool/impl.py", line 137, in _do_get
    return self._create_connection()
  File "/usr/local/lib/python3.8/site-packages/sqlalchemy/pool/base.py", line 309, in _create_connection
    return _ConnectionRecord(self)
  File "/usr/local/lib/python3.8/site-packages/sqlalchemy/pool/base.py", line 440, in __init__
    self.__connect(first_connect_check=True)
  File "/usr/local/lib/python3.8/site-packages/sqlalchemy/pool/base.py", line 661, in __connect
    pool.logger.debug("Error on connect(): %s", e)
  File "/usr/local/lib/python3.8/site-packages/sqlalchemy/util/langhelpers.py", line 68, in __exit__
    compat.raise_(
  File "/usr/local/lib/python3.8/site-packages/sqlalchemy/util/compat.py", line 182, in raise_
    raise exception
  File "/usr/local/lib/python3.8/site-packages/sqlalchemy/pool/base.py", line 656, in __connect
    connection = pool._invoke_creator(self)
  File "/usr/local/lib/python3.8/site-packages/sqlalchemy/engine/strategies.py", line 114, in connect
    return dialect.connect(*cargs, **cparams)
  File "/usr/local/lib/python3.8/site-packages/sqlalchemy/engine/default.py", line 493, in connect
    return self.dbapi.connect(*cargs, **cparams)
  File "/usr/local/lib/python3.8/site-packages/mysql/connector/__init__.py", line 264, in connect
    return CMySQLConnection(*args, **kwargs)
  File "/usr/local/lib/python3.8/site-packages/mysql/connector/connection_cext.py", line 80, in __init__
    self.connect(**kwargs)
  File "/usr/local/lib/python3.8/site-packages/mysql/connector/abstracts.py", line 966, in connect
    self._open_connection()
  File "/usr/local/lib/python3.8/site-packages/mysql/connector/connection_cext.py", line 218, in _open_connection
    raise errors.get_mysql_exception(msg=exc.msg, errno=exc.errno,
sqlalchemy.exc.ProgrammingError: (mysql.connector.errors.ProgrammingError) 1045 (28000): Access denied for user 'roo'@'172.17.0.1' (using password: YES)
(Background on this error at: http://sqlalche.me/e/13/f405)
